Workbook

Sheet Raw data & Hourly Summary
U2: Great N Rd
B3: Job No. | E3: : NZNth13356 | S3: Wingate St | AA3: St Jude St
B4: Client | E4: : Auckland Transport
B5: Suburb | E5: : Preston Road Surveys
B6: Location | E6: : 2. Great N Rd / St Georges Rd / St Jude St / Wingate St
B8: Day/Date | E8: : Wed, 3 September 2025
B9: Weather | E9: : Fine
B10: Description | E10: : Classified Intersection Count
E11: : 15 mins Data
E12: Class 1 | G12: Class 2 | I12: Class 3 | S12: Great N Rd | X12: St Georges Rd
B13: Classifications | E13: Lights | G13: Heavies | I13: Buses
B15: Approach | E15: =S12 -> Great N Rd | Y15: =X12 -> St Georges Rd
B16: Direction | E16: Direction 1 | I16: Direction 2 | M16: Direction 3 | Q16: Direction 4 | U16: Direction 4U | Y16: Direction 5 | AC16: Direction 6 | AG16: Direction 7 | AK16: Direction 8 | AO16: Direction 8U
B17: Time Period | E17: =$E$13 -> Lights | F17: =$G$13 -> Heavies | G17: =$I$13 -> Buses | H17: Total | I17: =$E$13 -> Lights | J17: =$G$13 -> Heavies | K17: =$I$13 -> Buses | L17: Total | M17: =$E$13 -> Lights | N17: =$G$13 -> Heavies | O17: =$I$13 -> Buses | P17: Total | Q17: =$E$13 -> Lights | R17: =$G$13 -> Heavies | S17: =$I$13 -> Buses | T17: Total | U17: =$E$13 -> Lights | V17: =$G$13 -> Heavies | W17: =$I$13 -> Buses | X17: Total | Y17: =$E$13 -> Lights | Z17: =$G$13 -> Heavies | AA17: =$I$13 -> Buses | AB17: Total | AC17: =$E$13 -> Lights | AD17: =$G$13 -> Heavies | AE17: =$I$13 -> Buses | AF17: Total | AG17: =$E$13 -> Lights | AH17: =$G$13 -> Heavies | AI17: =$I$13 -> Buses | AJ17: Total | AK17: =$E$13 -> Lights | AL17: =$G$13 -> Heavies | AM17: =$I$13 -> Buses | AN17: Total | AO17: =$E$13 -> Lights | AP17: =$G$13 -> Heavies | AQ17: =$I$13 -> Buses | AR17: Total
B18: 0.25 | C18: to | D18: =SUM(0.0416667/4)+B18 -> 0.26041667 | E18: 0 | F18: 0 | G18: 0 | H18: =SUM(E18:G18) -> 0 | I18: 26 | J18: 2 | K18: 3 | L18: =SUM(I18:K18) -> 31 | M18: 53 | N18: 0 | O18: 0 | P18: =SUM(M18:O18) -> 53 | Q18: 10 | R18: 0 | S18: 0 | T18: =SUM(Q18:S18) -> 10 | U18: 0 | V18: 0 | W18: 0 | X18: =SUM(U18:W18) -> 0 | Y18: 4 | Z18: 0 | AA18: 0 | AB18: =SUM(Y18:AA18) -> 4 | AC18: 0 | AD18: 0 | AE18: 0 | AF18: =SUM(AC18:AE18) -> 0 | AG18: 21 | AH18: 0 | AI18: 0 | AJ18: =SUM(AG18:AI18) -> 21 | AK18: 3 | AL18: 0 | AM18: 0 | AN18: =SUM(AK18:AM18) -> 3 | AO18: 0 | AP18: 0 | AQ18: 0 | AR18: =SUM(AO18:AQ18) -> 0
B19: =+D18 -> 0.26041667 | C19: to | D19: =SUM(0.0416667/4)+B19 -> 0.27083335 | E19: 0 | F19: 0 | G19: 0 | H19: =SUM(E19:G19) -> 0 | I19: 29 | J19: 2 | K19: 3 | L19: =SUM(I19:K19) -> 34 | M19: 100 | N19: 2 | O19: 1 | P19: =SUM(M19:O19) -> 103 | Q19: 14 | R19: 0 | S19: 0 | T19: =SUM(Q19:S19) -> 14 | U19: 0 | V19: 0 | W19: 0 | X19: =SUM(U19:W19) -> 0 | Y19: 3 | Z19: 0 | AA19: 0 | AB19: =SUM(Y19:AA19) -> 3 | AC19: 3 | AD19: 1 | AE19: 0 | AF19: =SUM(AC19:AE19) -> 4 | AG19: 22 | AH19: 0 | AI19: 0 | AJ19: =SUM(AG19:AI19) -> 22 | AK19: 8 | AL19: 0 | AM19: 0 | AN19: =SUM(AK19:AM19) -> 8 | AO19: 0 | AP19: 0 | AQ19: 0 | AR19: =SUM(AO19:AQ19) -> 0
B20: =+D19 -> 0.27083335 | C20: to | D20: =SUM(0.0416667/4)+B20 -> 0.28125002 | E20: 3 | F20: 0 | G20: 0 | H20: =SUM(E20:G20) -> 3 | I20: 30 | J20: 0 | K20: 6 | L20: =SUM(I20:K20) -> 36 | M20: 150 | N20: 1 | O20: 0 | P20: =SUM(M20:O20) -> 151 | Q20: 6 | R20: 1 | S20: 0 | T20: =SUM(Q20:S20) -> 7 | U20: 1 | V20: 0 | W20: 0 | X20: =SUM(U20:W20) -> 1 | Y20: 3 | Z20: 0 | AA20: 0 | AB20: =SUM(Y20:AA20) -> 3 | AC20: 1 | AD20: 0 | AE20: 0 | AF20: =SUM(AC20:AE20) -> 1 | AG20: 25 | AH20: 0 | AI20: 0 | AJ20: =SUM(AG20:AI20) -> 25 | AK20: 11 | AL20: 0 | AM20: 0 | AN20: =SUM(AK20:AM20) -> 11 | AO20: 0 | AP20: 0 | AQ20: 0 | AR20: =SUM(AO20:AQ20) -> 0
B21: =+D20 -> 0.28125002 | C21: to | D21: =SUM(0.0416667/4)+B21 -> 0.2916667 | E21: 0 | F21: 0 | G21: 0 | H21: =SUM(E21:G21) -> 0 | I21: 30 | J21: 0 | K21: 5 | L21: =SUM(I21:K21) -> 35 | M21: 193 | N21: 4 | O21: 0 | P21: =SUM(M21:O21) -> 197 | Q21: 4 | R21: 0 | S21: 0 | T21: =SUM(Q21:S21) -> 4 | U21: 0 | V21: 0 | W21: 0 | X21: =SUM(U21:W21) -> 0 | Y21: 2 | Z21: 0 | AA21: 0 | AB21: =SUM(Y21:AA21) -> 2 | AC21: 2 | AD21: 0 | AE21: 0 | AF21: =SUM(AC21:AE21) -> 2 | AG21: 38 | AH21: 1 | AI21: 0 | AJ21: =SUM(AG21:AI21) -> 39 | AK21: 13 | AL21: 0 | AM21: 0 | AN21: =SUM(AK21:AM21) -> 13 | AO21: 0 | AP21: 0 | AQ21: 0 | AR21: =SUM(AO21:AQ21) -> 0
B22: =+D21 -> 0.2916667 | C22: to | D22: =SUM(0.0416667/4)+B22 -> 0.30208337 | E22: 1 | F22: 0 | G22: 0 | H22: =SUM(E22:G22) -> 1 | I22: 34 | J22: 1 | K22: 4 | L22: =SUM(I22:K22) -> 39 | M22: 183 | N22: 2 | O22: 0 | P22: =SUM(M22:O22) -> 185 | Q22: 11 | R22: 0 | S22: 0 | T22: =SUM(Q22:S22) -> 11 | U22: 0 | V22: 0 | W22: 0 | X22: =SUM(U22:W22) -> 0 | Y22: 7 | Z22: 0 | AA22: 0 | AB22: =SUM(Y22:AA22) -> 7 | AC22: 0 | AD22: 0 | AE22: 0 | AF22: =SUM(AC22:AE22) -> 0 | AG22: 33 | AH22: 0 | AI22: 0 | AJ22: =SUM(AG22:AI22) -> 33 | AK22: 15 | AL22: 0 | AM22: 0 | AN22: =SUM(AK22:AM22) -> 15 | AO22: 0 | AP22: 0 | AQ22: 0 | AR22: =SUM(AO22:AQ22) -> 0
B23: =+D22 -> 0.30208337 | C23: to | D23: =SUM(0.0416667/4)+B23 -> 0.31250005 | E23: 0 | F23: 0 | G23: 0 | H23: =SUM(E23:G23) -> 0 | I23: 38 | J23: 4 | K23: 7 | L23: =SUM(I23:K23) -> 49 | M23: 171 | N23: 2 | O23: 0 | P23: =SUM(M23:O23) -> 173 | Q23: 11 | R23: 1 | S23: 0 | T23: =SUM(Q23:S23) -> 12 | U23: 1 | V23: 0 | W23: 0 | X23: =SUM(U23:W23) -> 1 | Y23: 10 | Z23: 0 | AA23: 0 | AB23: =SUM(Y23:AA23) -> 10 | AC23: 3 | AD23: 0 | AE23: 0 | AF23: =SUM(AC23:AE23) -> 3 | AG23: 45 | AH23: 3 | AI23: 0 | AJ23: =SUM(AG23:AI23) -> 48 | AK23: 22 | AL23: 0 | AM23: 0 | AN23: =SUM(AK23:AM23) -> 22 | AO23: 0 | AP23: 0 | AQ23: 0 | AR23: =SUM(AO23:AQ23) -> 0
B24: =+D23 -> 0.31250005 | C24: to | D24: =SUM(0.0416667/4)+B24 -> 0.32291672 | E24: 1 | F24: 0 | G24: 0 | H24: =SUM(E24:G24) -> 1 | I24: 40 | J24: 1 | K24: 7 | L24: =SUM(I24:K24) -> 48 | M24: 161 | N24: 0 | O24: 0 | P24: =SUM(M24:O24) -> 161 | Q24: 14 | R24: 0 | S24: 0 | T24: =SUM(Q24:S24) -> 14 | U24: 1 | V24: 0 | W24: 0 | X24: =SUM(U24:W24) -> 1 | Y24: 7 | Z24: 0 | AA24: 0 | AB24: =SUM(Y24:AA24) -> 7 | AC24: 1 | AD24: 0 | AE24: 0 | AF24: =SUM(AC24:AE24) -> 1 | AG24: 51 | AH24: 1 | AI24: 0 | AJ24: =SUM(AG24:AI24) -> 52 | AK24: 33 | AL24: 0 | AM24: 0 | AN24: =SUM(AK24:AM24) -> 33 | AO24: 0 | AP24: 0 | AQ24: 0 | AR24: =SUM(AO24:AQ24) -> 0
B25: =+D24 -> 0.32291672 | C25: to | D25: =SUM(0.0416667/4)+B25 -> 0.3333334 | E25: 0 | F25: 0 | G25: 0 | H25: =SUM(E25:G25) -> 0 | I25: 36 | J25: 0 | K25: 6 | L25: =SUM(I25:K25) -> 42 | M25: 142 | N25: 0 | O25: 0 | P25: =SUM(M25:O25) -> 142 | Q25: 9 | R25: 0 | S25: 0 | T25: =SUM(Q25:S25) -> 9 | U25: 0 | V25: 0 | W25: 0 | X25: =SUM(U25:W25) -> 0 | Y25: 6 | Z25: 0 | AA25: 0 | AB25: =SUM(Y25:AA25) -> 6 | AC25: 0 | AD25: 0 | AE25: 0 | AF25: =SUM(AC25:AE25) -> 0 | AG25: 65 | AH25: 0 | AI25: 0 | AJ25: =SUM(AG25:AI25) -> 65 | AK25: 34 | AL25: 0 | AM25: 0 | AN25: =SUM(AK25:AM25) -> 34 | AO25: 1 | AP25: 0 | AQ25: 0 | AR25: =SUM(AO25:AQ25) -> 1
B26: =+D25 -> 0.3333334 | C26: to | D26: =SUM(0.0416667/4)+B26 -> 0.34375007 | E26: 0 | F26: 0 | G26: 0 | H26: =SUM(E26:G26) -> 0 | I26: 23 | J26: 1 | K26: 5 | L26: =SUM(I26:K26) -> 29 | M26: 120 | N26: 2 | O26: 0 | P26: =SUM(M26:O26) -> 122 | Q26: 12 | R26: 1 | S26: 0 | T26: =SUM(Q26:S26) -> 13 | U26: 1 | V26: 0 | W26: 0 | X26: =SUM(U26:W26) -> 1 | Y26: 15 | Z26: 0 | AA26: 0 | AB26: =SUM(Y26:AA26) -> 15 | AC26: 3 | AD26: 0 | AE26: 0 | AF26: =SUM(AC26:AE26) -> 3 | AG26: 79 | AH26: 2 | AI26: 0 | AJ26: =SUM(AG26:AI26) -> 81 | AK26: 39 | AL26: 1 | AM26: 0 | AN26: =SUM(AK26:AM26) -> 40 | AO26: 0 | AP26: 0 | AQ26: 0 | AR26: =SUM(AO26:AQ26) -> 0
B27: =+D26 -> 0.34375007 | C27: to | D27: =SUM(0.0416667/4)+B27 -> 0.35416675 | E27: 0 | F27: 0 | G27: 0 | H27: =SUM(E27:G27) -> 0 | I27: 37 | J27: 1 | K27: 6 | L27: =SUM(I27:K27) -> 44 | M27: 113 | N27: 1 | O27: 0 | P27: =SUM(M27:O27) -> 114 | Q27: 12 | R27: 1 | S27: 0 | T27: =SUM(Q27:S27) -> 13 | U27: 0 | V27: 0 | W27: 0 | X27: =SUM(U27:W27) -> 0 | Y27: 11 | Z27: 0 | AA27: 0 | AB27: =SUM(Y27:AA27) -> 11 | AC27: 4 | AD27: 0 | AE27: 0 | AF27: =SUM(AC27:AE27) -> 4 | AG27: 93 | AH27: 2 | AI27: 0 | AJ27: =SUM(AG27:AI27) -> 95 | AK27: 37 | AL27: 0 | AM27: 0 | AN27: =SUM(AK27:AM27) -> 37 | AO27: 0 | AP27: 0 | AQ27: 0 | AR27: =SUM(AO27:AQ27) -> 0
B28: =+D27 -> 0.35416675 | C28: to | D28: =SUM(0.0416667/4)+B28 -> 0.36458342 | E28: 3 | F28: 0 | G28: 0 | H28: =SUM(E28:G28) -> 3 | I28: 46 | J28: 1 | K28: 5 | L28: =SUM(I28:K28) -> 52 | M28: 110 | N28: 0 | O28: 0 | P28: =SUM(M28:O28) -> 110 | Q28: 15 | R28: 0 | S28: 0 | T28: =SUM(Q28:S28) -> 15 | U28: 0 | V28: 0 | W28: 0 | X28: =SUM(U28:W28) -> 0 | Y28: 16 | Z28: 0 | AA28: 0 | AB28: =SUM(Y28:AA28) -> 16 | AC28: 4 | AD28: 0 | AE28: 0 | AF28: =SUM(AC28:AE28) -> 4 | AG28: 72 | AH28: 1 | AI28: 0 | AJ28: =SUM(AG28:AI28) -> 73 | AK28: 36 | AL28: 0 | AM28: 0 | AN28: =SUM(AK28:AM28) -> 36 | AO28: 1 | AP28: 0 | AQ28: 0 | AR28: =SUM(AO28:AQ28) -> 1
B29: =+D28 -> 0.36458342 | C29: to | D29: =SUM(0.0416667/4)+B29 -> 0.3750001 | E29: 0 | F29: 0 | G29: 0 | H29: =SUM(E29:G29) -> 0 | I29: 46 | J29: 4 | K29: 4 | L29: =SUM(I29:K29) -> 54 | M29: 97 | N29: 2 | O29: 0 | P29: =SUM(M29:O29) -> 99 | Q29: 24 | R29: 1 | S29: 0 | T29: =SUM(Q29:S29) -> 25 | U29: 1 | V29: 0 | W29: 0 | X29: =SUM(U29:W29) -> 1 | Y29: 20 | Z29: 0 | AA29: 0 | AB29: =SUM(Y29:AA29) -> 20 | AC29: 9 | AD29: 1 | AE29: 0 | AF29: =SUM(AC29:AE29) -> 10 | AG29: 76 | AH29: 0 | AI29: 0 | AJ29: =SUM(AG29:AI29) -> 76 | AK29: 27 | AL29: 0 | AM29: 0 | AN29: =SUM(AK29:AM29) -> 27 | AO29: 0 | AP29: 0 | AQ29: 0 | AR29: =SUM(AO29:AQ29) -> 0
B30: =+D29 -> 0.3750001 | C30: to | D30: =SUM(0.0416667/4)+B30 -> 0.38541677 | E30: 0 | F30: 0 | G30: 0 | H30: =SUM(E30:G30) -> 0 | I30: 57 | J30: 2 | K30: 6 | L30: =SUM(I30:K30) -> 65 | M30: 88 | N30: 2 | O30: 0 | P30: =SUM(M30:O30) -> 90 | Q30: 17 | R30: 0 | S30: 0 | T30: =SUM(Q30:S30) -> 17 | U30: 1 | V30: 0 | W30: 0 | X30: =SUM(U30:W30) -> 1 | Y30: 15 | Z30: 3 | AA30: 0 | AB30: =SUM(Y30:AA30) -> 18 | AC30: 5 | AD30: 0 | AE30: 0 | AF30: =SUM(AC30:AE30) -> 5 | AG30: 62 | AH30: 1 | AI30: 0 | AJ30: =SUM(AG30:AI30) -> 63 | AK30: 16 | AL30: 0 | AM30: 0 | AN30: =SUM(AK30:AM30) -> 16 | AO30: 1 | AP30: 0 | AQ30: 0 | AR30: =SUM(AO30:AQ30) -> 1
... B33: =+D32 -> 0.40625012 | C33: to | D33: =SUM(0.0416667/4)+B33 -> 0.4166668 | E33: 5 | F33: 1 | G33: 0 | H33: =SUM(E33:G33) -> 6 | I33: 62 | J33: 1 | K33: 3 | L33: =SUM(I33:K33) -> 66 | M33: 62 | N33: 0 | O33: 0 | P33: =SUM(M33:O33) -> 62 | Q33: 13 | R33: 1 | S33: 0 | T33: =SUM(Q33:S33) -> 14 | U33: 0 | V33: 0 | W33: 0 | X33: =SUM(U33:W33) -> 0 | Y33: 11 | Z33: 0 | AA33: 0 | AB33: =SUM(Y33:AA33) -> 11 | AC33: 4 | AD33: 0 | AE33: 0 | AF33: =SUM(AC33:AE33) -> 4 | AG33: 38 | AH33: 1 | AI33: 0 | AJ33: =SUM(AG33:AI33) -> 39 | AK33: 16 | AL33: 0 | AM33: 0 | AN33: =SUM(AK33:AM33) -> 16 | AO33: 0 | AP33: 0 | AQ33: 0 | AR33: =SUM(AO33:AQ33) -> 0
B34: AM Totals | E34: =SUM(E18:E33) -> 21 | F34: =SUM(F18:F33) -> 1 | G34: =SUM(G18:G33) -> 0 | H34: =SUM(E34:G34) -> 22 | I34: =SUM(I18:I33) -> 633 | J34: =SUM(J18:J33) -> 22 | K34: =SUM(K18:K33) -> 79 | L34: =SUM(I34:K34) -> 734 | M34: =SUM(M18:M33) -> 1900 | N34: =SUM(N18:N33) -> 21 | O34: =SUM(O18:O33) -> 1 | P34: =SUM(M34:O34) -> 1922 | Q34: =SUM(Q18:Q33) -> 216 | R34: =SUM(R18:R33) -> 6 | S34: =SUM(S18:S33) -> 0 | T34: =SUM(Q34:S34) -> 222 | U34: =SUM(U18:U33) -> 8 | V34: =SUM(V18:V33) -> 0 | W34: =SUM(W18:W33) -> 0 | X34: =SUM(U34:W34) -> 8 | Y34: =SUM(Y18:Y33) -> 168 | Z34: =SUM(Z18:Z33) -> 4 | AA34: =SUM(AA18:AA33) -> 0 | AB34: =SUM(Y34:AA34) -> 172 | AC34: =SUM(AC18:AC33) -> 42 | AD34: =SUM(AD18:AD33) -> 2 | AE34: =SUM(AE18:AE33) -> 0 | AF34: =SUM(AC34:AE34) -> 44 | AG34: =SUM(AG18:AG33) -> 787 | AH34: =SUM(AH18:AH33) -> 18 | AI34: =SUM(AI18:AI33) -> 0 | AJ34: =SUM(AG34:AI34) -> 805 | AK34: =SUM(AK18:AK33) -> 331 | AL34: =SUM(AL18:AL33) -> 1 | AM34: =SUM(AM18:AM33) -> 0 | AN34: =SUM(AK34:AM34) -> 332 | AO34: =SUM(AO18:AO33) -> 3 | AP34: =SUM(AP18:AP33) -> 0 | AQ34: =SUM(AQ18:AQ33) -> 0 | AR34: =SUM(AO34:AQ34) -> 3
B35: 0.60416667 | C35: to | D35: =SUM(0.0416667/4)+B35 -> 0.61458334 | E35: 5 | F35: 0 | G35: 0 | H35: =SUM(E35:G35) -> 5 | I35: 58 | J35: 0 | K35: 5 | L35: =SUM(I35:K35) -> 63 | M35: 72 | N35: 2 | O35: 0 | P35: =SUM(M35:O35) -> 74 | Q35: 27 | R35: 0 | S35: 0 | T35: =SUM(Q35:S35) -> 27 | U35: 1 | V35: 0 | W35: 0 | X35: =SUM(U35:W35) -> 1 | Y35: 23 | Z35: 0 | AA35: 0 | AB35: =SUM(Y35:AA35) -> 23 | AC35: 6 | AD35: 0 | AE35: 0 | AF35: =SUM(AC35:AE35) -> 6 | AG35: 44 | AH35: 1 | AI35: 0 | AJ35: =SUM(AG35:AI35) -> 45 | AK35: 11 | AL35: 0 | AM35: 0 | AN35: =SUM(AK35:AM35) -> 11 | AO35: 3 | AP35: 0 | AQ35: 0 | AR35: =SUM(AO35:AQ35) -> 3
B36: =+D35 -> 0.61458334 | C36: to | D36: =SUM(0.0416667/4)+B36 -> 0.62500002 | E36: 5 | F36: 1 | G36: 0 | H36: =SUM(E36:G36) -> 6 | I36: 75 | J36: 1 | K36: 3 | L36: =SUM(I36:K36) -> 79 | M36: 66 | N36: 1 | O36: 1 | P36: =SUM(M36:O36) -> 68 | Q36: 24 | R36: 0 | S36: 0 | T36: =SUM(Q36:S36) -> 24 | U36: 7 | V36: 0 | W36: 0 | X36: =SUM(U36:W36) -> 7 | Y36: 21 | Z36: 1 | AA36: 0 | AB36: =SUM(Y36:AA36) -> 22 | AC36: 4 | AD36: 0 | AE36: 0 | AF36: =SUM(AC36:AE36) -> 4 | AG36: 45 | AH36: 2 | AI36: 0 | AJ36: =SUM(AG36:AI36) -> 47 | AK36: 8 | AL36: 0 | AM36: 0 | AN36: =SUM(AK36:AM36) -> 8 | AO36: 0 | AP36: 0 | AQ36: 0 | AR36: =SUM(AO36:AQ36) -> 0
B37: =+D36 -> 0.62500002 | C37: to | D37: =SUM(0.0416667/4)+B37 -> 0.63541669 | E37: 2 | F37: 0 | G37: 0 | H37: =SUM(E37:G37) -> 2 | I37: 49 | J37: 0 | K37: 4 | L37: =SUM(I37:K37) -> 53 | M37: 66 | N37: 1 | O37: 0 | P37: =SUM(M37:O37) -> 67 | Q37: 37 | R37: 1 | S37: 0 | T37: =SUM(Q37:S37) -> 38 | U37: 0 | V37: 0 | W37: 0 | X37: =SUM(U37:W37) -> 0 | Y37: 27 | Z37: 0 | AA37: 0 | AB37: =SUM(Y37:AA37) -> 27 | AC37: 7 | AD37: 0 | AE37: 0 | AF37: =SUM(AC37:AE37) -> 7 | AG37: 65 | AH37: 1 | AI37: 0 | AJ37: =SUM(AG37:AI37) -> 66 | AK37: 14 | AL37: 0 | AM37: 0 | AN37: =SUM(AK37:AM37) -> 14 | AO37: 2 | AP37: 0 | AQ37: 0 | AR37: =SUM(AO37:AQ37) -> 2
B38: =+D37 -> 0.63541669 | C38: to | D38: =SUM(0.0416667/4)+B38 -> 0.64583337 | E38: 3 | F38: 0 | G38: 0 | H38: =SUM(E38:G38) -> 3 | I38: 53 | J38: 0 | K38: 4 | L38: =SUM(I38:K38) -> 57 | M38: 79 | N38: 0 | O38: 0 | P38: =SUM(M38:O38) -> 79 | Q38: 22 | R38: 2 | S38: 0 | T38: =SUM(Q38:S38) -> 24 | U38: 1 | V38: 0 | W38: 0 | X38: =SUM(U38:W38) -> 1 | Y38: 16 | Z38: 0 | AA38: 0 | AB38: =SUM(Y38:AA38) -> 16 | AC38: 13 | AD38: 0 | AE38: 0 | AF38: =SUM(AC38:AE38) -> 13 | AG38: 39 | AH38: 0 | AI38: 0 | AJ38: =SUM(AG38:AI38) -> 39 | AK38: 21 | AL38: 0 | AM38: 0 | AN38: =SUM(AK38:AM38) -> 21 | AO38: 2 | AP38: 0 | AQ38: 0 | AR38: =SUM(AO38:AQ38) -> 2
B39: =+D38 -> 0.64583337 | C39: to | D39: =SUM(0.0416667/4)+B39 -> 0.65625004 | E39: 4 | F39: 0 | G39: 0 | H39: =SUM(E39:G39) -> 4 | I39: 64 | J39: 1 | K39: 4 | L39: =SUM(I39:K39) -> 69 | M39: 89 | N39: 0 | O39: 0 | P39: =SUM(M39:O39) -> 89 | Q39: 37 | R39: 0 | S39: 0 | T39: =SUM(Q39:S39) -> 37 | U39: 4 | V39: 0 | W39: 0 | X39: =SUM(U39:W39) -> 4 | Y39: 19 | Z39: 0 | AA39: 0 | AB39: =SUM(Y39:AA39) -> 19 | AC39: 7 | AD39: 0 | AE39: 0 | AF39: =SUM(AC39:AE39) -> 7 | AG39: 49 | AH39: 3 | AI39: 0 | AJ39: =SUM(AG39:AI39) -> 52 | AK39: 15 | AL39: 0 | AM39: 0 | AN39: =SUM(AK39:AM39) -> 15 | AO39: 0 | AP39: 0 | AQ39: 0 | AR39: =SUM(AO39:AQ39) -> 0
B40: =+D39 -> 0.65625004 | C40: to | D40: =SUM(0.0416667/4)+B40 -> 0.66666672 | E40: 5 | F40: 0 | G40: 0 | H40: =SUM(E40:G40) -> 5 | I40: 37 | J40: 0 | K40: 4 | L40: =SUM(I40:K40) -> 41 | M40: 68 | N40: 2 | O40: 0 | P40: =SUM(M40:O40) -> 70 | Q40: 31 | R40: 0 | S40: 0 | T40: =SUM(Q40:S40) -> 31 | U40: 0 | V40: 0 | W40: 0 | X40: =SUM(U40:W40) -> 0 | Y40: 14 | Z40: 0 | AA40: 0 | AB40: =SUM(Y40:AA40) -> 14 | AC40: 13 | AD40: 0 | AE40: 0 | AF40: =SUM(AC40:AE40) -> 13 | AG40: 25 | AH40: 0 | AI40: 0 | AJ40: =SUM(AG40:AI40) -> 25 | AK40: 19 | AL40: 0 | AM40: 0 | AN40: =SUM(AK40:AM40) -> 19 | AO40: 0 | AP40: 0 | AQ40: 0 | AR40: =SUM(AO40:AQ40) -> 0
B41: =+D40 -> 0.66666672 | C41: to | D41: =SUM(0.0416667/4)+B41 -> 0.67708339 | E41: 2 | F41: 0 | G41: 0 | H41: =SUM(E41:G41) -> 2 | I41: 64 | J41: 1 | K41: 5 | L41: =SUM(I41:K41) -> 70 | M41: 84 | N41: 0 | O41: 0 | P41: =SUM(M41:O41) -> 84 | Q41: 23 | R41: 1 | S41: 0 | T41: =SUM(Q41:S41) -> 24 | U41: 2 | V41: 0 | W41: 0 | X41: =SUM(U41:W41) -> 2 | Y41: 14 | Z41: 2 | AA41: 0 | AB41: =SUM(Y41:AA41) -> 16 | AC41: 10 | AD41: 0 | AE41: 0 | AF41: =SUM(AC41:AE41) -> 10 | AG41: 27 | AH41: 0 | AI41: 0 | AJ41: =SUM(AG41:AI41) -> 27 | AK41: 5 | AL41: 0 | AM41: 0 | AN41: =SUM(AK41:AM41) -> 5 | AO41: 3 | AP41: 0 | AQ41: 0 | AR41: =SUM(AO41:AQ41) -> 3
B42: =+D41 -> 0.67708339 | C42: to | D42: =SUM(0.0416667/4)+B42 -> 0.68750007 | E42: 6 | F42: 0 | G42: 0 | H42: =SUM(E42:G42) -> 6 | I42: 58 | J42: 0 | K42: 2 | L42: =SUM(I42:K42) -> 60 | M42: 71 | N42: 0 | O42: 0 | P42: =SUM(M42:O42) -> 71 | Q42: 18 | R42: 1 | S42: 0 | T42: =SUM(Q42:S42) -> 19 | U42: 1 | V42: 0 | W42: 0 | X42: =SUM(U42:W42) -> 1 | Y42: 19 | Z42: 0 | AA42: 0 | AB42: =SUM(Y42:AA42) -> 19 | AC42: 7 | AD42: 0 | AE42: 0 | AF42: =SUM(AC42:AE42) -> 7 | AG42: 29 | AH42: 0 | AI42: 0 | AJ42: =SUM(AG42:AI42) -> 29 | AK42: 10 | AL42: 0 | AM42: 0 | AN42: =SUM(AK42:AM42) -> 10 | AO42: 0 | AP42: 0 | AQ42: 0 | AR42: =SUM(AO42:AQ42) -> 0
B43: =+D42 -> 0.68750007 | C43: to | D43: =SUM(0.0416667/4)+B43 -> 0.69791674 | E43: 7 | F43: 0 | G43: 0 | H43: =SUM(E43:G43) -> 7 | I43: 79 | J43: 0 | K43: 5 | L43: =SUM(I43:K43) -> 84 | M43: 94 | N43: 0 | O43: 0 | P43: =SUM(M43:O43) -> 94 | Q43: 23 | R43: 0 | S43: 0 | T43: =SUM(Q43:S43) -> 23 | U43: 3 | V43: 0 | W43: 0 | X43: =SUM(U43:W43) -> 3 | Y43: 28 | Z43: 0 | AA43: 0 | AB43: =SUM(Y43:AA43) -> 28 | AC43: 10 | AD43: 0 | AE43: 0 | AF43: =SUM(AC43:AE43) -> 10 | AG43: 30 | AH43: 0 | AI43: 0 | AJ43: =SUM(AG43:AI43) -> 30 | AK43: 9 | AL43: 0 | AM43: 0 | AN43: =SUM(AK43:AM43) -> 9 | AO43: 2 | AP43: 0 | AQ43: 0 | AR43: =SUM(AO43:AQ43) -> 2
B44: =+D43 -> 0.69791674 | C44: to | D44: =SUM(0.0416667/4)+B44 -> 0.70833342 | E44: 5 | F44: 0 | G44: 0 | H44: =SUM(E44:G44) -> 5 | I44: 63 | J44: 0 | K44: 2 | L44: =SUM(I44:K44) -> 65 | M44: 81 | N44: 0 | O44: 0 | P44: =SUM(M44:O44) -> 81 | Q44: 23 | R44: 0 | S44: 0 | T44: =SUM(Q44:S44) -> 23 | U44: 3 | V44: 0 | W44: 0 | X44: =SUM(U44:W44) -> 3 | Y44: 22 | Z44: 0 | AA44: 0 | AB44: =SUM(Y44:AA44) -> 22 | AC44: 9 | AD44: 0 | AE44: 0 | AF44: =SUM(AC44:AE44) -> 9 | AG44: 50 | AH44: 1 | AI44: 0 | AJ44: =SUM(AG44:AI44) -> 51 | AK44: 13 | AL44: 0 | AM44: 0 | AN44: =SUM(AK44:AM44) -> 13 | AO44: 2 | AP44: 0 | AQ44: 0 | AR44: =SUM(AO44:AQ44) -> 2
B45: =+D44 -> 0.70833342 | C45: to | D45: =SUM(0.0416667/4)+B45 -> 0.71875009 | E45: 6 | F45: 0 | G45: 0 | H45: =SUM(E45:G45) -> 6 | I45: 74 | J45: 0 | K45: 5 | L45: =SUM(I45:K45) -> 79 | M45: 84 | N45: 0 | O45: 0 | P45: =SUM(M45:O45) -> 84 | Q45: 38 | R45: 0 | S45: 0 | T45: =SUM(Q45:S45) -> 38 | U45: 5 | V45: 0 | W45: 0 | X45: =SUM(U45:W45) -> 5 | Y45: 30 | Z45: 0 | AA45: 0 | AB45: =SUM(Y45:AA45) -> 30 | AC45: 9 | AD45: 0 | AE45: 0 | AF45: =SUM(AC45:AE45) -> 9 | AG45: 39 | AH45: 1 | AI45: 0 | AJ45: =SUM(AG45:AI45) -> 40 | AK45: 10 | AL45: 0 | AM45: 0 | AN45: =SUM(AK45:AM45) -> 10 | AO45: 0 | AP45: 0 | AQ45: 0 | AR45: =SUM(AO45:AQ45) -> 0
...

Sheet Peak Hr Summary
O2: ='Raw data & Hourly Summary'!$U$2 -> Great N Rd
B3: Job No. | E3: ='Raw data & Hourly Summary'!E3 -> : NZNth13356 | M3: ='Raw data & Hourly Summary'!$S$3 -> Wingate St | U3: ='Raw data & Hourly Summary'!$AA$3 -> St Jude St
B4: Client | E4: ='Raw data & Hourly Summary'!E4 -> : Auckland Transport
B5: Suburb | E5: ='Raw data & Hourly Summary'!E5 -> : Preston Road Surveys
B6: Location | E6: ='Raw data & Hourly Summary'!E6 -> : 2. Great N Rd / St Georges Rd / St Jude St / Wingate St
B8: Day/Date | E8: ='Raw data & Hourly Summary'!E8 -> : Wed, 3 September 2025
B9: Weather | E9: ='Raw data & Hourly Summary'!E9 -> : Fine
B10: Description | E10: ='Raw data & Hourly Summary'!E10 -> : Classified Intersection Count
E11: : Peak Hour Summary
M12: ='Raw data & Hourly Summary'!$S$12 -> Great N Rd | R12: ='Raw data & Hourly Summary'!$X$12 -> St Georges Rd
B14: Approach | E14: =M12 -> Great N Rd | I14: =R12 -> St Georges Rd | M14: =U3 -> St Jude St | Q14: =O2 -> Great N Rd | U14: =M3 -> Wingate St | Y14: Grand Total
B15: Time Period | E15: ='Raw data & Hourly Summary'!$E$13 -> Lights | F15: ='Raw data & Hourly Summary'!$G$13 -> Heavies | G15: ='Raw data & Hourly Summary'!$I$13 -> Buses | H15: Total | I15: ='Raw data & Hourly Summary'!$E$13 -> Lights | J15: ='Raw data & Hourly Summary'!$G$13 -> Heavies | K15: ='Raw data & Hourly Summary'!$I$13 -> Buses | L15: Total | M15: ='Raw data & Hourly Summary'!$E$13 -> Lights | N15: ='Raw data & Hourly Summary'!$G$13 -> Heavies | O15: ='Raw data & Hourly Summary'!$I$13 -> Buses | P15: Total | Q15: ='Raw data & Hourly Summary'!$E$13 -> Lights | R15: ='Raw data & Hourly Summary'!$G$13 -> Heavies | S15: ='Raw data & Hourly Summary'!$I$13 -> Buses | T15: Total | U15: ='Raw data & Hourly Summary'!$E$13 -> Lights | V15: ='Raw data & Hourly Summary'!$G$13 -> Heavies | W15: ='Raw data & Hourly Summary'!$I$13 -> Buses | X15: Total
A16: AM | B16: =AG18 -> 0.34375001 | C16: to | D16: =SUM(0.04166667)+B16 -> 0.38541668 | E16: =AH18 -> 667 | F16: =AI18 -> 15 | G16: =AJ18 -> 21 | H16: =AK18 -> 703 | I16: =AL18 -> 505 | J16: =AM18 -> 8 | K16: =AN18 -> 0 | L16: =AO18 -> 513 | ... Y16: =BB18 -> 2265 | AG16: 1 | AH16: 2 | AI16: 3 | AJ16: 4 | AK16: 5 | AL16: 6 | AM16: 7 | AN16: 8 | AO16: 9 | AP16: 10 | AQ16: 11 | AR16: 12 | AS16: 13 | AT16: 14 | AU16: 15 | AV16: 16 | AW16: 17 | AX16: 18 | AY16: 19 | AZ16: 20 | BA16: 21 | BB16: 22
A17: PM | B17: =AG19 -> 0.67708334 | C17: to | D17: =SUM(0.04166667)+B17 -> 0.71875001 | E17: =AH19 -> 742 | F17: =AI19 -> 1 | G17: =AJ19 -> 14 | H17: =AK19 -> 757 | I17: =AL19 -> 328 | J17: =AM19 -> 2 | K17: =AN19 -> 0 | L17: =AO19 -> 330 | ... Y17: =BB19 -> 2665 | AH17: AM max | AI17: =MAX(Y21:Y33) -> 2265 | AJ17: PM max | AK17: =MAX(Y35:Y47) -> 2665
AF18: AM | AG18: =MIN(AG21:AG33) -> 0.34375001 | AH18: =VLOOKUP($AG$18,$AG$21:$BB$33,AH16) -> 667 | AI18: =VLOOKUP($AG$18,$AG$21:$BB$33,AI16) -> 15 | AJ18: =VLOOKUP($AG$18,$AG$21:$BB$33,AJ16) -> 21 | AK18: =VLOOKUP($AG$18,$AG$21:$BB$33,AK16) -> 703 | AL18: =VLOOKUP($AG$18,$AG$21:$BB$33,AL16) -> 505 | AM18: =VLOOKUP($AG$18,$AG$21:$BB$33,AM16) -> 8 | AN18: =VLOOKUP($AG$18,$AG$21:$BB$33,AN16) -> 0 | AO18: =VLOOKUP($AG$18,$AG$21:$BB$33,AO16) -> 513 | ... BB18: =VLOOKUP($AG$18,$AG$21:$BB$33,BB16) -> 2265
B19: Approach | E19: =M12 -> Great N Rd | I19: =R12 -> St Georges Rd | M19: =U3 -> St Jude St | Q19: =O2 -> Great N Rd | U19: =M3 -> Wingate St | Y19: Grand Total | AF19: PM | AG19: =MIN(AG35:AG47) -> 0.67708334 | AH19: =VLOOKUP($AG$19,$AG$35:$BB$47,AH16) -> 742 | AI19: =VLOOKUP($AG$19,$AG$35:$BB$47,AI16) -> 1 | AJ19: =VLOOKUP($AG$19,$AG$35:$BB$47,AJ16) -> 14 | AK19: =VLOOKUP($AG$19,$AG$35:$BB$47,AK16) -> 757 | AL19: =VLOOKUP($AG$19,$AG$35:$BB$47,AL16) -> 328 | AM19: =VLOOKUP($AG$19,$AG$35:$BB$47,AM16) -> 2 | AN19: =VLOOKUP($AG$19,$AG$35:$BB$47,AN16) -> 0 | AO19: =VLOOKUP($AG$19,$AG$35:$BB$47,AO16) -> 330 | ... BB19: =VLOOKUP($AG$19,$AG$35:$BB$47,BB16) -> 2665
B20: Time Period | E20: ='Raw data & Hourly Summary'!$E$13 -> Lights | F20: ='Raw data & Hourly Summary'!$G$13 -> Heavies | G20: ='Raw data & Hourly Summary'!$I$13 -> Buses | H20: Total | I20: ='Raw data & Hourly Summary'!$E$13 -> Lights | J20: ='Raw data & Hourly Summary'!$G$13 -> Heavies | K20: ='Raw data & Hourly Summary'!$I$13 -> Buses | L20: Total | M20: ='Raw data & Hourly Summary'!$E$13 -> Lights | N20: ='Raw data & Hourly Summary'!$G$13 -> Heavies | O20: ='Raw data & Hourly Summary'!$I$13 -> Buses | P20: Total | Q20: ='Raw data & Hourly Summary'!$E$13 -> Lights | R20: ='Raw data & Hourly Summary'!$G$13 -> Heavies | S20: ='Raw data & Hourly Summary'!$I$13 -> Buses | T20: Total | U20: ='Raw data & Hourly Summary'!$E$13 -> Lights | V20: ='Raw data & Hourly Summary'!$G$13 -> Heavies | W20: ='Raw data & Hourly Summary'!$I$13 -> Buses | X20: Total
B21: ='Raw data & Hourly Summary'!B18 -> 0.25 | C21: to | D21: =SUM(0.04166667)+B21 -> 0.29166667 | E21: =SUM('Raw data & Hourly Summary'!E107,'Raw data & Hourly Summary'!I107,'Raw data & Hourly Summary'!M107,'Raw data & Hourly Summary'!Q107,'Raw data & Hourly Summary'!U107) -> 649 | F21: =SUM('Raw data & Hourly Summary'!F107,'Raw data & Hourly Summary'!J107,'Raw data & Hourly Summary'!N107,'Raw data & Hourly Summary'!R107,'Raw data & Hourly Summary'!V107) -> 12 | G21: =SUM('Raw data & Hourly Summary'!G107,'Raw data & Hourly Summary'!K107,'Raw data & Hourly Summary'!O107,'Raw data & Hourly Summary'!S107,'Raw data & Hourly Summary'!W107) -> 18 | H21: =SUM(E21:G21) -> 679 | I21: =SUM('Raw data & Hourly Summary'!Y107,'Raw data & Hourly Summary'!AC107,'Raw data & Hourly Summary'!AG107,'Raw data & Hourly Summary'!AK107,'Raw data & Hourly Summary'!AO107) -> 159 | J21: =SUM('Raw data & Hourly Summary'!Z107,'Raw data & Hourly Summary'!AD107,'Raw data & Hourly Summary'!AH107,'Raw data & Hourly Summary'!AL107,'Raw data & Hourly Summary'!AP107) -> 2 | K21: =SUM('Raw data & Hourly Summary'!AA107,'Raw data & Hourly Summary'!AE107,'Raw data & Hourly Summary'!AI107,'Raw data & Hourly Summary'!AM107,'Raw data & Hourly Summary'!AQ107) -> 0 | L21: =SUM(I21:K21) -> 161 | M21: =SUM('Raw data & Hourly Summary'!E139,'Raw data & Hourly Summary'!I139,'Raw data & Hourly Summary'!M139,'Raw data & Hourly Summary'!Q139,'Raw data & Hourly Summary'!U139) -> 103 | N21: =SUM('Raw data & Hourly Summary'!F139,'Raw data & Hourly Summary'!J139,'Raw data & Hourly Summary'!N139,'Raw data & Hourly Summary'!R139,'Raw data & Hourly Summary'!V139) -> 8 | O21: =SUM('Raw data & Hourly Summary'!G139,'Raw data & Hourly Summary'!K139,'Raw data & Hourly Summary'!O139,'Raw data & Hourly Summary'!S139,'Raw data & Hourly Summary'!W139) -> 0 | P21: =SUM(M21:O21) -> 111 | Q21: =SUM('Raw data & Hourly Summary'!Y139,'Raw data & Hourly Summary'!AC139,'Raw data & Hourly Summary'!AG139,'Raw data & Hourly Summary'!AK139,'Raw data & Hourly Summary'!AO139) -> 142 | R21: =SUM('Raw data & Hourly Summary'!Z139,'Raw data & Hourly Summary'!AD139,'Raw data & Hourly Summary'!AH139,'Raw data & Hourly Summary'!AL139,'Raw data & Hourly Summary'!AP139) -> 8 | S21: =SUM('Raw data & Hourly Summary'!AA139,'Raw data & Hourly Summary'!AE139,'Raw data & Hourly Summary'!AI139,'Raw data & Hourly Summary'!AM139,'Raw data & Hourly Summary'!AQ139) -> 12 | T21: =SUM(Q21:S21) -> 162 | U21: =SUM('Raw data & Hourly Summary'!AS139,'Raw data & Hourly Summary'!AW139,'Raw data & Hourly Summary'!BA139,'Raw data & Hourly Summary'!BE139,'Raw data & Hourly Summary'!BI139) -> 51 | V21: =SUM('Raw data & Hourly Summary'!AT139,'Raw data & Hourly Summary'!AX139,'Raw data & Hourly Summary'!BB139,'Raw data & Hourly Summary'!BF139,'Raw data & Hourly Summary'!BJ139) -> 1 | W21: =SUM('Raw data & Hourly Summary'!AU139,'Raw data & Hourly Summary'!AY139,'Raw data & Hourly Summary'!BC139,'Raw data & Hourly Summary'!BG139,'Raw data & Hourly Summary'!BK139) -> 0 | X21: =SUM(U21:W21) -> 52 | Y21: =H21+L21+P21+T21+X21 -> 1165 | AG21: =IF($BD21=$Y21,B21,"") | AH21: =IF($BD21=$Y21,E21,"") | AI21: =IF($BD21=$Y21,F21,"") | AJ21: =IF($BD21=$Y21,G21,"") | AK21: =IF($BD21=$Y21,H21,"") | AL21: =IF($BD21=$Y21,I21,"") | AM21: =IF($BD21=$Y21,J21,"") | AN21: =IF($BD21=$Y21,K21,"") | AO21: =IF($BD21=$Y21,L21,"") | ... BB21: =IF($BD21=$Y21,Y21,"") | BD21: =+BD22 -> 2265
B22: =SUM(0.04166667/4+B21) -> 0.26041667 | C22: to | D22: =SUM(0.04166667)+B22 -> 0.30208334 | E22: =SUM('Raw data & Hourly Summary'!E108,'Raw data & Hourly Summary'!I108,'Raw data & Hourly Summary'!M108,'Raw data & Hourly Summary'!Q108,'Raw data & Hourly Summary'!U108) -> 789 | F22: =SUM('Raw data & Hourly Summary'!F108,'Raw data & Hourly Summary'!J108,'Raw data & Hourly Summary'!N108,'Raw data & Hourly Summary'!R108,'Raw data & Hourly Summary'!V108) -> 13 | G22: =SUM('Raw data & Hourly Summary'!G108,'Raw data & Hourly Summary'!K108,'Raw data & Hourly Summary'!O108,'Raw data & Hourly Summary'!S108,'Raw data & Hourly Summary'!W108) -> 19 | H22: =SUM(E22:G22) -> 821 | I22: =SUM('Raw data & Hourly Summary'!Y108,'Raw data & Hourly Summary'!AC108,'Raw data & Hourly Summary'!AG108,'Raw data & Hourly Summary'!AK108,'Raw data & Hourly Summary'!AO108) -> 186 | J22: =SUM('Raw data & Hourly Summary'!Z108,'Raw data & Hourly Summary'!AD108,'Raw data & Hourly Summary'!AH108,'Raw data & Hourly Summary'!AL108,'Raw data & Hourly Summary'!AP108) -> 2 | K22: =SUM('Raw data & Hourly Summary'!AA108,'Raw data & Hourly Summary'!AE108,'Raw data & Hourly Summary'!AI108,'Raw data & Hourly Summary'!AM108,'Raw data & Hourly Summary'!AQ108) -> 0 | L22: =SUM(I22:K22) -> 188 | M22: =SUM('Raw data & Hourly Summary'!E140,'Raw data & Hourly Summary'!I140,'Raw data & Hourly Summary'!M140,'Raw data & Hourly Summary'!Q140,'Raw data & Hourly Summary'!U140) -> 117 | N22: =SUM('Raw data & Hourly Summary'!F140,'Raw data & Hourly Summary'!J140,'Raw data & Hourly Summary'!N140,'Raw data & Hourly Summary'!R140,'Raw data & Hourly Summary'!V140) -> 8 | O22: =SUM('Raw data & Hourly Summary'!G140,'Raw data & Hourly Summary'!K140,'Raw data & Hourly Summary'!O140,'Raw data & Hourly Summary'!S140,'Raw data & Hourly Summary'!W140) -> 0 | P22: =SUM(M22:O22) -> 125 | Q22: =SUM('Raw data & Hourly Summary'!Y140,'Raw data & Hourly Summary'!AC140,'Raw data & Hourly Summary'!AG140,'Raw data & Hourly Summary'!AK140,'Raw data & Hourly Summary'!AO140) -> 158 | R22: =SUM('Raw data & Hourly Summary'!Z140,'Raw data & Hourly Summary'!AD140,'Raw data & Hourly Summary'!AH140,'Raw data & Hourly Summary'!AL140,'Raw data & Hourly Summary'!AP140) -> 8 | S22: =SUM('Raw data & Hourly Summary'!AA140,'Raw data & Hourly Summary'!AE140,'Raw data & Hourly Summary'!AI140,'Raw data & Hourly Summary'!AM140,'Raw data & Hourly Summary'!AQ140) -> 9 | T22: =SUM(Q22:S22) -> 175 | U22: =SUM('Raw data & Hourly Summary'!AS140,'Raw data & Hourly Summary'!AW140,'Raw data & Hourly Summary'!BA140,'Raw data & Hourly Summary'!BE140,'Raw data & Hourly Summary'!BI140) -> 54 | V22: =SUM('Raw data & Hourly Summary'!AT140,'Raw data & Hourly Summary'!AX140,'Raw data & Hourly Summary'!BB140,'Raw data & Hourly Summary'!BF140,'Raw data & Hourly Summary'!BJ140) -> 1 | W22: =SUM('Raw data & Hourly Summary'!AU140,'Raw data & Hourly Summary'!AY140,'Raw data & Hourly Summary'!BC140,'Raw data & Hourly Summary'!BG140,'Raw data & Hourly Summary'!BK140) -> 0 | X22: =SUM(U22:W22) -> 55 | Y22: =H22+L22+P22+T22+X22 -> 1364 | AG22: =IF($BD22=$Y22,B22,"") | AH22: =IF($BD22=$Y22,E22,"") | AI22: =IF($BD22=$Y22,F22,"") | AJ22: =IF($BD22=$Y22,G22,"") | AK22: =IF($BD22=$Y22,H22,"") | AL22: =IF($BD22=$Y22,I22,"") | AM22: =IF($BD22=$Y22,J22,"") | AN22: =IF($BD22=$Y22,K22,"") | AO22: =IF($BD22=$Y22,L22,"") | ... BB22: =IF($BD22=$Y22,Y22,"") | BD22: =+BD23 -> 2265
B23: =SUM(0.04166667/4+B22) -> 0.27083333 | C23: to | D23: =SUM(0.04166667)+B23 -> 0.3125 | E23: =SUM('Raw data & Hourly Summary'!E109,'Raw data & Hourly Summary'!I109,'Raw data & Hourly Summary'!M109,'Raw data & Hourly Summary'!Q109,'Raw data & Hourly Summary'!U109) -> 867 | F23: =SUM('Raw data & Hourly Summary'!F109,'Raw data & Hourly Summary'!J109,'Raw data & Hourly Summary'!N109,'Raw data & Hourly Summary'!R109,'Raw data & Hourly Summary'!V109) -> 16 | G23: =SUM('Raw data & Hourly Summary'!G109,'Raw data & Hourly Summary'!K109,'Raw data & Hourly Summary'!O109,'Raw data & Hourly Summary'!S109,'Raw data & Hourly Summary'!W109) -> 22 | H23: =SUM(E23:G23) -> 905 | I23: =SUM('Raw data & Hourly Summary'!Y109,'Raw data & Hourly Summary'!AC109,'Raw data & Hourly Summary'!AG109,'Raw data & Hourly Summary'!AK109,'Raw data & Hourly Summary'!AO109) -> 230 | J23: =SUM('Raw data & Hourly Summary'!Z109,'Raw data & Hourly Summary'!AD109,'Raw data & Hourly Summary'!AH109,'Raw data & Hourly Summary'!AL109,'Raw data & Hourly Summary'!AP109) -> 4 | K23: =SUM('Raw data & Hourly Summary'!AA109,'Raw data & Hourly Summary'!AE109,'Raw data & Hourly Summary'!AI109,'Raw data & Hourly Summary'!AM109,'Raw data & Hourly Summary'!AQ109) -> 0 | L23: =SUM(I23:K23) -> 234 | M23: =SUM('Raw data & Hourly Summary'!E141,'Raw data & Hourly Summary'!I141,'Raw data & Hourly Summary'!M141,'Raw data & Hourly Summary'!Q141,'Raw data & Hourly Summary'!U141) -> 149 | N23: =SUM('Raw data & Hourly Summary'!F141,'Raw data & Hourly Summary'!J141,'Raw data & Hourly Summary'!N141,'Raw data & Hourly Summary'!R141,'Raw data & Hourly Summary'!V141) -> 7 | O23: =SUM('Raw data & Hourly Summary'!G141,'Raw data & Hourly Summary'!K141,'Raw data & Hourly Summary'!O141,'Raw data & Hourly Summary'!S141,'Raw data & Hourly Summary'!W141) -> 0 | P23: =SUM(M23:O23) -> 156 | Q23: =SUM('Raw data & Hourly Summary'!Y141,'Raw data & Hourly Summary'!AC141,'Raw data & Hourly Summary'!AG141,'Raw data & Hourly Summary'!AK141,'Raw data & Hourly Summary'!AO141) -> 186 | R23: =SUM('Raw data & Hourly Summary'!Z141,'Raw data & Hourly Summary'!AD141,'Raw data & Hourly Summary'!AH141,'Raw data & Hourly Summary'!AL141,'Raw data & Hourly Summary'!AP141) -> 7 | S23: =SUM('Raw data & Hourly Summary'!AA141,'Raw data & Hourly Summary'!AE141,'Raw data & Hourly Summary'!AI141,'Raw data & Hourly Summary'!AM141,'Raw data & Hourly Summary'!AQ141) -> 8 | T23: =SUM(Q23:S23) -> 201 | U23: =SUM('Raw data & Hourly Summary'!AS141,'Raw data & Hourly Summary'!AW141,'Raw data & Hourly Summary'!BA141,'Raw data & Hourly Summary'!BE141,'Raw data & Hourly Summary'!BI141) -> 67 | V23: =SUM('Raw data & Hourly Summary'!AT141,'Raw data & Hourly Summary'!AX141,'Raw data & Hourly Summary'!BB141,'Raw data & Hourly Summary'!BF141,'Raw data & Hourly Summary'!BJ141) -> 2 | W23: =SUM('Raw data & Hourly Summary'!AU141,'Raw data & Hourly Summary'!AY141,'Raw data & Hourly Summary'!BC141,'Raw data & Hourly Summary'!BG141,'Raw data & Hourly Summary'!BK141) -> 0 | X23: =SUM(U23:W23) -> 69 | Y23: =H23+L23+P23+T23+X23 -> 1565 | AG23: =IF($BD23=$Y23,B23,"") | AH23: =IF($BD23=$Y23,E23,"") | AI23: =IF($BD23=$Y23,F23,"") | AJ23: =IF($BD23=$Y23,G23,"") | AK23: =IF($BD23=$Y23,H23,"") | AL23: =IF($BD23=$Y23,I23,"") | AM23: =IF($BD23=$Y23,J23,"") | AN23: =IF($BD23=$Y23,K23,"") | AO23: =IF($BD23=$Y23,L23,"") | ... BB23: =IF($BD23=$Y23,Y23,"") | BD23: =+BD24 -> 2265
B24: =SUM(0.04166667/4+B23) -> 0.28125 | C24: to | D24: =SUM(0.04166667)+B24 -> 0.32291667 | E24: =SUM('Raw data & Hourly Summary'!E110,'Raw data & Hourly Summary'!I110,'Raw data & Hourly Summary'!M110,'Raw data & Hourly Summary'!Q110,'Raw data & Hourly Summary'!U110) -> 894 | F24: =SUM('Raw data & Hourly Summary'!F110,'Raw data & Hourly Summary'!J110,'Raw data & Hourly Summary'!N110,'Raw data & Hourly Summary'!R110,'Raw data & Hourly Summary'!V110) -> 15 | G24: =SUM('Raw data & Hourly Summary'!G110,'Raw data & Hourly Summary'!K110,'Raw data & Hourly Summary'!O110,'Raw data & Hourly Summary'!S110,'Raw data & Hourly Summary'!W110) -> 23 | H24: =SUM(E24:G24) -> 932 | I24: =SUM('Raw data & Hourly Summary'!Y110,'Raw data & Hourly Summary'!AC110,'Raw data & Hourly Summary'!AG110,'Raw data & Hourly Summary'!AK110,'Raw data & Hourly Summary'!AO110) -> 282 | J24: =SUM('Raw data & Hourly Summary'!Z110,'Raw data & Hourly Summary'!AD110,'Raw data & Hourly Summary'!AH110,'Raw data & Hourly Summary'!AL110,'Raw data & Hourly Summary'!AP110) -> 5 | K24: =SUM('Raw data & Hourly Summary'!AA110,'Raw data & Hourly Summary'!AE110,'Raw data & Hourly Summary'!AI110,'Raw data & Hourly Summary'!AM110,'Raw data & Hourly Summary'!AQ110) -> 0 | L24: =SUM(I24:K24) -> 287 | M24: =SUM('Raw data & Hourly Summary'!E142,'Raw data & Hourly Summary'!I142,'Raw data & Hourly Summary'!M142,'Raw data & Hourly Summary'!Q142,'Raw data & Hourly Summary'!U142) -> 173 | N24: =SUM('Raw data & Hourly Summary'!F142,'Raw data & Hourly Summary'!J142,'Raw data & Hourly Summary'!N142,'Raw data & Hourly Summary'!R142,'Raw data & Hourly Summary'!V142) -> 11 | O24: =SUM('Raw data & Hourly Summary'!G142,'Raw data & Hourly Summary'!K142,'Raw data & Hourly Summary'!O142,'Raw data & Hourly Summary'!S142,'Raw data & Hourly Summary'!W142) -> 0 | P24: =SUM(M24:O24) -> 184 | Q24: =SUM('Raw data & Hourly Summary'!Y142,'Raw data & Hourly Summary'!AC142,'Raw data & Hourly Summary'!AG142,'Raw data & Hourly Summary'!AK142,'Raw data & Hourly Summary'!AO142) -> 207 | R24: =SUM('Raw data & Hourly Summary'!Z142,'Raw data & Hourly Summary'!AD142,'Raw data & Hourly Summary'!AH142,'Raw data & Hourly Summary'!AL142,'Raw data & Hourly Summary'!AP142) -> 4 | S24: =SUM('Raw data & Hourly Summary'!AA142,'Raw data & Hourly Summary'!AE142,'Raw data & Hourly Summary'!AI142,'Raw data & Hourly Summary'!AM142,'Raw data & Hourly Summary'!AQ142) -> 10 | T24: =SUM(Q24:S24) -> 221 | U24: =SUM('Raw data & Hourly Summary'!AS142,'Raw data & Hourly Summary'!AW142,'Raw data & Hourly Summary'!BA142,'Raw data & Hourly Summary'!BE142,'Raw data & Hourly Summary'!BI142) -> 100 | V24: =SUM('Raw data & Hourly Summary'!AT142,'Raw data & Hourly Summary'!AX142,'Raw data & Hourly Summary'!BB142,'Raw data & Hourly Summary'!BF142,'Raw data & Hourly Summary'!BJ142) -> 2 | W24: =SUM('Raw data & Hourly Summary'!AU142,'Raw data & Hourly Summary'!AY142,'Raw data & Hourly Summary'!BC142,'Raw data & Hourly Summary'!BG142,'Raw data & Hourly Summary'!BK142) -> 0 | X24: =SUM(U24:W24) -> 102 | Y24: =H24+L24+P24+T24+X24 -> 1726 | AG24: =IF($BD24=$Y24,B24,"") | AH24: =IF($BD24=$Y24,E24,"") | AI24: =IF($BD24=$Y24,F24,"") | AJ24: =IF($BD24=$Y24,G24,"") | AK24: =IF($BD24=$Y24,H24,"") | AL24: =IF($BD24=$Y24,I24,"") | AM24: =IF($BD24=$Y24,J24,"") | AN24: =IF($BD24=$Y24,K24,"") | AO24: =IF($BD24=$Y24,L24,"") | ... BB24: =IF($BD24=$Y24,Y24,"") | BD24: =+BD25 -> 2265
B25: =SUM(0.04166667/4+B24) -> 0.29166667 | C25: to | D25: =SUM(0.04166667)+B25 -> 0.33333334 | E25: =SUM('Raw data & Hourly Summary'!E111,'Raw data & Hourly Summary'!I111,'Raw data & Hourly Summary'!M111,'Raw data & Hourly Summary'!Q111,'Raw data & Hourly Summary'!U111) -> 854 | F25: =SUM('Raw data & Hourly Summary'!F111,'Raw data & Hourly Summary'!J111,'Raw data & Hourly Summary'!N111,'Raw data & Hourly Summary'!R111,'Raw data & Hourly Summary'!V111) -> 11 | G25: =SUM('Raw data & Hourly Summary'!G111,'Raw data & Hourly Summary'!K111,'Raw data & Hourly Summary'!O111,'Raw data & Hourly Summary'!S111,'Raw data & Hourly Summary'!W111) -> 24 | H25: =SUM(E25:G25) -> 889 | I25: =SUM('Raw data & Hourly Summary'!Y111,'Raw data & Hourly Summary'!AC111,'Raw data & Hourly Summary'!AG111,'Raw data & Hourly Summary'!AK111,'Raw data & Hourly Summary'!AO111) -> 333 | J25: =SUM('Raw data & Hourly Summary'!Z111,'Raw data & Hourly Summary'!AD111,'Raw data & Hourly Summary'!AH111,'Raw data & Hourly Summary'!AL111,'Raw data & Hourly Summary'!AP111) -> 4 | K25: =SUM('Raw data & Hourly Summary'!AA111,'Raw data & Hourly Summary'!AE111,'Raw data & Hourly Summary'!AI111,'Raw data & Hourly Summary'!AM111,'Raw data & Hourly Summary'!AQ111) -> 0 | L25: =SUM(I25:K25) -> 337 | M25: =SUM('Raw data & Hourly Summary'!E143,'Raw data & Hourly Summary'!I143,'Raw data & Hourly Summary'!M143,'Raw data & Hourly Summary'!Q143,'Raw data & Hourly Summary'!U143) -> 208 | N25: =SUM('Raw data & Hourly Summary'!F143,'Raw data & Hourly Summary'!J143,'Raw data & Hourly Summary'!N143,'Raw data & Hourly Summary'!R143,'Raw data & Hourly Summary'!V143) -> 11 | O25: =SUM('Raw data & Hourly Summary'!G143,'Raw data & Hourly Summary'!K143,'Raw data & Hourly Summary'!O143,'Raw data & Hourly Summary'!S143,'Raw data & Hourly Summary'!W143) -> 0 | P25: =SUM(M25:O25) -> 219 | Q25: =SUM('Raw data & Hourly Summary'!Y143,'Raw data & Hourly Summary'!AC143,'Raw data & Hourly Summary'!AG143,'Raw data & Hourly Summary'!AK143,'Raw data & Hourly Summary'!AO143) -> 236 | R25: =SUM('Raw data & Hourly Summary'!Z143,'Raw data & Hourly Summary'!AD143,'Raw data & Hourly Summary'!AH143,'Raw data & Hourly Summary'!AL143,'Raw data & Hourly Summary'!AP143) -> 8 | S25: =SUM('Raw data & Hourly Summary'!AA143,'Raw data & Hourly Summary'!AE143,'Raw data & Hourly Summary'!AI143,'Raw data & Hourly Summary'!AM143,'Raw data & Hourly Summary'!AQ143) -> 12 | T25: =SUM(Q25:S25) -> 256 | U25: =SUM('Raw data & Hourly Summary'!AS143,'Raw data & Hourly Summary'!AW143,'Raw data & Hourly Summary'!BA143,'Raw data & Hourly Summary'!BE143,'Raw data & Hourly Summary'!BI143) -> 134 | V25: =SUM('Raw data & Hourly Summary'!AT143,'Raw data & Hourly Summary'!AX143,'Raw data & Hourly Summary'!BB143,'Raw data & Hourly Summary'!BF143,'Raw data & Hourly Summary'!BJ143) -> 4 | W25: =SUM('Raw data & Hourly Summary'!AU143,'Raw data & Hourly Summary'!AY143,'Raw data & Hourly Summary'!BC143,'Raw data & Hourly Summary'!BG143,'Raw data & Hourly Summary'!BK143) -> 0 | X25: =SUM(U25:W25) -> 138 | Y25: =H25+L25+P25+T25+X25 -> 1839 | AG25: =IF($BD25=$Y25,B25,"") | AH25: =IF($BD25=$Y25,E25,"") | AI25: =IF($BD25=$Y25,F25,"") | AJ25: =IF($BD25=$Y25,G25,"") | AK25: =IF($BD25=$Y25,H25,"") | AL25: =IF($BD25=$Y25,I25,"") | AM25: =IF($BD25=$Y25,J25,"") | AN25: =IF($BD25=$Y25,K25,"") | AO25: =IF($BD25=$Y25,L25,"") | ... BB25: =IF($BD25=$Y25,Y25,"") | BD25: =+BD26 -> 2265
B26: =SUM(0.04166667/4+B25) -> 0.30208334 | C26: to | D26: =SUM(0.04166667)+B26 -> 0.34375001 | E26: =SUM('Raw data & Hourly Summary'!E112,'Raw data & Hourly Summary'!I112,'Raw data & Hourly Summary'!M112,'Raw data & Hourly Summary'!Q112,'Raw data & Hourly Summary'!U112) -> 781 | F26: =SUM('Raw data & Hourly Summary'!F112,'Raw data & Hourly Summary'!J112,'Raw data & Hourly Summary'!N112,'Raw data & Hourly Summary'!R112,'Raw data & Hourly Summary'!V112) -> 12 | G26: =SUM('Raw data & Hourly Summary'!G112,'Raw data & Hourly Summary'!K112,'Raw data & Hourly Summary'!O112,'Raw data & Hourly Summary'!S112,'Raw data & Hourly Summary'!W112) -> 25 | H26: =SUM(E26:G26) -> 818 | I26: =SUM('Raw data & Hourly Summary'!Y112,'Raw data & Hourly Summary'!AC112,'Raw data & Hourly Summary'!AG112,'Raw data & Hourly Summary'!AK112,'Raw data & Hourly Summary'!AO112) -> 414 | J26: =SUM('Raw data & Hourly Summary'!Z112,'Raw data & Hourly Summary'!AD112,'Raw data & Hourly Summary'!AH112,'Raw data & Hourly Summary'!AL112,'Raw data & Hourly Summary'!AP112) -> 7 | K26: =SUM('Raw data & Hourly Summary'!AA112,'Raw data & Hourly Summary'!AE112,'Raw data & Hourly Summary'!AI112,'Raw data & Hourly Summary'!AM112,'Raw data & Hourly Summary'!AQ112) -> 0 | L26: =SUM(I26:K26) -> 421 | M26: =SUM('Raw data & Hourly Summary'!E144,'Raw data & Hourly Summary'!I144,'Raw data & Hourly Summary'!M144,'Raw data & Hourly Summary'!Q144,'Raw data & Hourly Summary'!U144) -> 246 | N26: =SUM('Raw data & Hourly Summary'!F144,'Raw data & Hourly Summary'!J144,'Raw data & Hourly Summary'!N144,'Raw data & Hourly Summary'!R144,'Raw data & Hourly Summary'!V144) -> 9 | O26: =SUM('Raw data & Hourly Summary'!G144,'Raw data & Hourly Summary'!K144,'Raw data & Hourly Summary'!O144,'Raw data & Hourly Summary'!S144,'Raw data & Hourly Summary'!W144) -> 1 | P26: =SUM(M26:O26) -> 256 | Q26: =SUM('Raw data & Hourly Summary'!Y144,'Raw data & Hourly Summary'!AC144,'Raw data & Hourly Summary'!AG144,'Raw data & Hourly Summary'!AK144,'Raw data & Hourly Summary'!AO144) -> 274 | R26: =SUM('Raw data & Hourly Summary'!Z144,'Raw data & Hourly Summary'!AD144,'Raw data & Hourly Summary'!AH144,'Raw data & Hourly Summary'!AL144,'Raw data & Hourly Summary'!AP144) -> 10 | S26: =SUM('Raw data & Hourly Summary'!AA144,'Raw data & Hourly Summary'!AE144,'Raw data & Hourly Summary'!AI144,'Raw data & Hourly Summary'!AM144,'Raw data & Hourly Summary'!AQ144) -> 16 | T26: =SUM(Q26:S26) -> 300 | U26: =SUM('Raw data & Hourly Summary'!AS144,'Raw data & Hourly Summary'!AW144,'Raw data & Hourly Summary'!BA144,'Raw data & Hourly Summary'!BE144,'Raw data & Hourly Summary'!BI144) -> 189 | V26: =SUM('Raw data & Hourly Summary'!AT144,'Raw data & Hourly Summary'!AX144,'Raw data & Hourly Summary'!BB144,'Raw data & Hourly Summary'!BF144,'Raw data & Hourly Summary'!BJ144) -> 4 | W26: =SUM('Raw data & Hourly Summary'!AU144,'Raw data & Hourly Summary'!AY144,'Raw data & Hourly Summary'!BC144,'Raw data & Hourly Summary'!BG144,'Raw data & Hourly Summary'!BK144) -> 0 | X26: =SUM(U26:W26) -> 193 | Y26: =H26+L26+P26+T26+X26 -> 1988 | AG26: =IF($BD26=$Y26,B26,"") | AH26: =IF($BD26=$Y26,E26,"") | AI26: =IF($BD26=$Y26,F26,"") | AJ26: =IF($BD26=$Y26,G26,"") | AK26: =IF($BD26=$Y26,H26,"") | AL26: =IF($BD26=$Y26,I26,"") | AM26: =IF($BD26=$Y26,J26,"") | AN26: =IF($BD26=$Y26,K26,"") | AO26: =IF($BD26=$Y26,L26,"") | ... BB26: =IF($BD26=$Y26,Y26,"") | BD26: =+BD27 -> 2265
B27: =SUM(0.04166667/4+B26) -> 0.3125 | C27: to | D27: =SUM(0.04166667)+B27 -> 0.35416667 | E27: =SUM('Raw data & Hourly Summary'!E113,'Raw data & Hourly Summary'!I113,'Raw data & Hourly Summary'!M113,'Raw data & Hourly Summary'!Q113,'Raw data & Hourly Summary'!U113) -> 722 | F27: =SUM('Raw data & Hourly Summary'!F113,'Raw data & Hourly Summary'!J113,'Raw data & Hourly Summary'!N113,'Raw data & Hourly Summary'!R113,'Raw data & Hourly Summary'!V113) -> 8 | G27: =SUM('Raw data & Hourly Summary'!G113,'Raw data & Hourly Summary'!K113,'Raw data & Hourly Summary'!O113,'Raw data & Hourly Summary'!S113,'Raw data & Hourly Summary'!W113) -> 24 | H27: =SUM(E27:G27) -> 754 | I27: =SUM('Raw data & Hourly Summary'!Y113,'Raw data & Hourly Summary'!AC113,'Raw data & Hourly Summary'!AG113,'Raw data & Hourly Summary'!AK113,'Raw data & Hourly Summary'!AO113) -> 479 | J27: =SUM('Raw data & Hourly Summary'!Z113,'Raw data & Hourly Summary'!AD113,'Raw data & Hourly Summary'!AH113,'Raw data & Hourly Summary'!AL113,'Raw data & Hourly Summary'!AP113) -> 6 | K27: =SUM('Raw data & Hourly Summary'!AA113,'Raw data & Hourly Summary'!AE113,'Raw data & Hourly Summary'!AI113,'Raw data & Hourly Summary'!AM113,'Raw data & Hourly Summary'!AQ113) -> 0 | L27: =SUM(I27:K27) -> 485 | M27: =SUM('Raw data & Hourly Summary'!E145,'Raw data & Hourly Summary'!I145,'Raw data & Hourly Summary'!M145,'Raw data & Hourly Summary'!Q145,'Raw data & Hourly Summary'!U145) -> 300 | N27: =SUM('Raw data & Hourly Summary'!F145,'Raw data & Hourly Summary'!J145,'Raw data & Hourly Summary'!N145,'Raw data & Hourly Summary'!R145,'Raw data & Hourly Summary'!V145) -> 8 | O27: =SUM('Raw data & Hourly Summary'!G145,'Raw data & Hourly Summary'!K145,'Raw data & Hourly Summary'!O145,'Raw data & Hourly Summary'!S145,'Raw data & Hourly Summary'!W145) -> 1 | P27: =SUM(M27:O27) -> 309 | Q27: =SUM('Raw data & Hourly Summary'!Y145,'Raw data & Hourly Summary'!AC145,'Raw data & Hourly Summary'!AG145,'Raw data & Hourly Summary'!AK145,'Raw data & Hourly Summary'!AO145) -> 315 | R27: =SUM('Raw data & Hourly Summary'!Z145,'Raw data & Hourly Summary'!AD145,'Raw data & Hourly Summary'!AH145,'Raw data & Hourly Summary'!AL145,'Raw data & Hourly Summary'!AP145) -> 10 | S27: =SUM('Raw data & Hourly Summary'!AA145,'Raw data & Hourly Summary'!AE145,'Raw data & Hourly Summary'!AI145,'Raw data & Hourly Summary'!AM145,'Raw data & Hourly Summary'!AQ145) -> 23 | T27: =SUM(Q27:S27) -> 348 | U27: =SUM('Raw data & Hourly Summary'!AS145,'Raw data & Hourly Summary'!AW145,'Raw data & Hourly Summary'!BA145,'Raw data & Hourly Summary'!BE145,'Raw data & Hourly Summary'!BI145) -> 217 | V27: =SUM('Raw data & Hourly Summary'!AT145,'Raw data & Hourly Summary'!AX145,'Raw data & Hourly Summary'!BB145,'Raw data & Hourly Summary'!BF145,'Raw data & Hourly Summary'!BJ145) -> 3 | W27: =SUM('Raw data & Hourly Summary'!AU145,'Raw data & Hourly Summary'!AY145,'Raw data & Hourly Summary'!BC145,'Raw data & Hourly Summary'!BG145,'Raw data & Hourly Summary'!BK145) -> 0 | X27: =SUM(U27:W27) -> 220 | Y27: =H27+L27+P27+T27+X27 -> 2116 | AG27: =IF($BD27=$Y27,B27,"") | AH27: =IF($BD27=$Y27,E27,"") | AI27: =IF($BD27=$Y27,F27,"") | AJ27: =IF($BD27=$Y27,G27,"") | AK27: =IF($BD27=$Y27,H27,"") | AL27: =IF($BD27=$Y27,I27,"") | AM27: =IF($BD27=$Y27,J27,"") | AN27: =IF($BD27=$Y27,K27,"") | AO27: =IF($BD27=$Y27,L27,"") | ... BB27: =IF($BD27=$Y27,Y27,"") | BD27: =+BD28 -> 2265
B28: =SUM(0.04166667/4+B27) -> 0.32291667 | C28: to | D28: =SUM(0.04166667)+B28 -> 0.36458334 | E28: =SUM('Raw data & Hourly Summary'!E114,'Raw data & Hourly Summary'!I114,'Raw data & Hourly Summary'!M114,'Raw data & Hourly Summary'!Q114,'Raw data & Hourly Summary'!U114) -> 679 | F28: =SUM('Raw data & Hourly Summary'!F114,'Raw data & Hourly Summary'!J114,'Raw data & Hourly Summary'!N114,'Raw data & Hourly Summary'!R114,'Raw data & Hourly Summary'!V114) -> 8 | G28: =SUM('Raw data & Hourly Summary'!G114,'Raw data & Hourly Summary'!K114,'Raw data & Hourly Summary'!O114,'Raw data & Hourly Summary'!S114,'Raw data & Hourly Summary'!W114) -> 22 | H28: =SUM(E28:G28) -> 709 | I28: =SUM('Raw data & Hourly Summary'!Y114,'Raw data & Hourly Summary'!AC114,'Raw data & Hourly Summary'!AG114,'Raw data & Hourly Summary'!AK114,'Raw data & Hourly Summary'!AO114) -> 516 | J28: =SUM('Raw data & Hourly Summary'!Z114,'Raw data & Hourly Summary'!AD114,'Raw data & Hourly Summary'!AH114,'Raw data & Hourly Summary'!AL114,'Raw data & Hourly Summary'!AP114) -> 6 | K28: =SUM('Raw data & Hourly Summary'!AA114,'Raw data & Hourly Summary'!AE114,'Raw data & Hourly Summary'!AI114,'Raw data & Hourly Summary'!AM114,'Raw data & Hourly Summary'!AQ114) -> 0 | L28: =SUM(I28:K28) -> 522 | M28: =SUM('Raw data & Hourly Summary'!E146,'Raw data & Hourly Summary'!I146,'Raw data & Hourly Summary'!M146,'Raw data & Hourly Summary'!Q146,'Raw data & Hourly Summary'!U146) -> 343 | N28: =SUM('Raw data & Hourly Summary'!F146,'Raw data & Hourly Summary'!J146,'Raw data & Hourly Summary'!N146,'Raw data & Hourly Summary'!R146,'Raw data & Hourly Summary'!V146) -> 7 | O28: =SUM('Raw data & Hourly Summary'!G146,'Raw data & Hourly Summary'!K146,'Raw data & Hourly Summary'!O146,'Raw data & Hourly Summary'!S146,'Raw data & Hourly Summary'!W146) -> 1 | P28: =SUM(M28:O28) -> 351 | Q28: =SUM('Raw data & Hourly Summary'!Y146,'Raw data & Hourly Summary'!AC146,'Raw data & Hourly Summary'!AG146,'Raw data & Hourly Summary'!AK146,'Raw data & Hourly Summary'!AO146) -> 369 | R28: =SUM('Raw data & Hourly Summary'!Z146,'Raw data & Hourly Summary'!AD146,'Raw data & Hourly Summary'!AH146,'Raw data & Hourly Summary'!AL146,'Raw data & Hourly Summary'!AP146) -> 12 | S28: =SUM('Raw data & Hourly Summary'!AA146,'Raw data & Hourly Summary'!AE146,'Raw data & Hourly Summary'!AI146,'Raw data & Hourly Summary'!AM146,'Raw data & Hourly Summary'!AQ146) -> 24 | T28: =SUM(Q28:S28) -> 405 | U28: =SUM('Raw data & Hourly Summary'!AS146,'Raw data & Hourly Summary'!AW146,'Raw data & Hourly Summary'!BA146,'Raw data & Hourly Summary'!BE146,'Raw data & Hourly Summary'!BI146) -> 199 | V28: =SUM('Raw data & Hourly Summary'!AT146,'Raw data & Hourly Summary'!AX146,'Raw data & Hourly Summary'!BB146,'Raw data & Hourly Summary'!BF146,'Raw data & Hourly Summary'!BJ146) -> 2 | W28: =SUM('Raw data & Hourly Summary'!AU146,'Raw data & Hourly Summary'!AY146,'Raw data & Hourly Summary'!BC146,'Raw data & Hourly Summary'!BG146,'Raw data & Hourly Summary'!BK146) -> 0 | X28: =SUM(U28:W28) -> 201 | Y28: =H28+L28+P28+T28+X28 -> 2188 | AG28: =IF($BD28=$Y28,B28,"") | AH28: =IF($BD28=$Y28,E28,"") | AI28: =IF($BD28=$Y28,F28,"") | AJ28: =IF($BD28=$Y28,G28,"") | AK28: =IF($BD28=$Y28,H28,"") | AL28: =IF($BD28=$Y28,I28,"") | AM28: =IF($BD28=$Y28,J28,"") | AN28: =IF($BD28=$Y28,K28,"") | AO28: =IF($BD28=$Y28,L28,"") | ... BB28: =IF($BD28=$Y28,Y28,"") | BD28: =+BD29 -> 2265
B29: =SUM(0.04166667/4+B28) -> 0.33333334 | C29: to | D29: =SUM(0.04166667)+B29 -> 0.37500001 | E29: =SUM('Raw data & Hourly Summary'!E115,'Raw data & Hourly Summary'!I115,'Raw data & Hourly Summary'!M115,'Raw data & Hourly Summary'!Q115,'Raw data & Hourly Summary'!U115) -> 660 | F29: =SUM('Raw data & Hourly Summary'!F115,'Raw data & Hourly Summary'!J115,'Raw data & Hourly Summary'!N115,'Raw data & Hourly Summary'!R115,'Raw data & Hourly Summary'!V115) -> 15 | G29: =SUM('Raw data & Hourly Summary'!G115,'Raw data & Hourly Summary'!K115,'Raw data & Hourly Summary'!O115,'Raw data & Hourly Summary'!S115,'Raw data & Hourly Summary'!W115) -> 20 | H29: =SUM(E29:G29) -> 695 | I29: =SUM('Raw data & Hourly Summary'!Y115,'Raw data & Hourly Summary'!AC115,'Raw data & Hourly Summary'!AG115,'Raw data & Hourly Summary'!AK115,'Raw data & Hourly Summary'!AO115) -> 542 | J29: =SUM('Raw data & Hourly Summary'!Z115,'Raw data & Hourly Summary'!AD115,'Raw data & Hourly Summary'!AH115,'Raw data & Hourly Summary'!AL115,'Raw data & Hourly Summary'!AP115) -> 7 | K29: =SUM('Raw data & Hourly Summary'!AA115,'Raw data & Hourly Summary'!AE115,'Raw data & Hourly Summary'!AI115,'Raw data & Hourly Summary'!AM115,'Raw data & Hourly Summary'!AQ115) -> 0 | L29: =SUM(I29:K29) -> 549 | M29: =SUM('Raw data & Hourly Summary'!E147,'Raw data & Hourly Summary'!I147,'Raw data & Hourly Summary'!M147,'Raw data & Hourly Summary'!Q147,'Raw data & Hourly Summary'!U147) -> 399 | N29: =SUM('Raw data & Hourly Summary'!F147,'Raw data & Hourly Summary'!J147,'Raw data & Hourly Summary'!N147,'Raw data & Hourly Summary'!R147,'Raw data & Hourly Summary'!V147) -> 6 | O29: =SUM('Raw data & Hourly Summary'!G147,'Raw data & Hourly Summary'!K147,'Raw data & Hourly Summary'!O147,'Raw data & Hourly Summary'!S147,'Raw data & Hourly Summary'!W147) -> 1 | P29: =SUM(M29:O29) -> 406 | Q29: =SUM('Raw data & Hourly Summary'!Y147,'Raw data & Hourly Summary'!AC147,'Raw data & Hourly Summary'!AG147,'Raw data & Hourly Summary'!AK147,'Raw data & Hourly Summary'!AO147) -> 408 | R29: =SUM('Raw data & Hourly Summary'!Z147,'Raw data & Hourly Summary'!AD147,'Raw data & Hourly Summary'!AH147,'Raw data & Hourly Summary'!AL147,'Raw data & Hourly Summary'!AP147) -> 11 | S29: =SUM('Raw data & Hourly Summary'!AA147,'Raw data & Hourly Summary'!AE147,'Raw data & Hourly Summary'!AI147,'Raw data & Hourly Summary'!AM147,'Raw data & Hourly Summary'!AQ147) -> 25 | T29: =SUM(Q29:S29) -> 444 | U29: =SUM('Raw data & Hourly Summary'!AS147,'Raw data & Hourly Summary'!AW147,'Raw data & Hourly Summary'!BA147,'Raw data & Hourly Summary'!BE147,'Raw data & Hourly Summary'!BI147) -> 169 | V29: =SUM('Raw data & Hourly Summary'!AT147,'Raw data & Hourly Summary'!AX147,'Raw data & Hourly Summary'!BB147,'Raw data & Hourly Summary'!BF147,'Raw data & Hourly Summary'!BJ147) -> 0 | W29: =SUM('Raw data & Hourly Summary'!AU147,'Raw data & Hourly Summary'!AY147,'Raw data & Hourly Summary'!BC147,'Raw data & Hourly Summary'!BG147,'Raw data & Hourly Summary'!BK147) -> 0 | X29: =SUM(U29:W29) -> 169 | Y29: =H29+L29+P29+T29+X29 -> 2263 | AG29: =IF($BD29=$Y29,B29,"") | AH29: =IF($BD29=$Y29,E29,"") | AI29: =IF($BD29=$Y29,F29,"") | AJ29: =IF($BD29=$Y29,G29,"") | AK29: =IF($BD29=$Y29,H29,"") | AL29: =IF($BD29=$Y29,I29,"") | AM29: =IF($BD29=$Y29,J29,"") | AN29: =IF($BD29=$Y29,K29,"") | AO29: =IF($BD29=$Y29,L29,"") | ... BB29: =IF($BD29=$Y29,Y29,"") | BD29: =+BD30 -> 2265
B30: =SUM(0.04166667/4+B29) -> 0.34375001 | C30: to | D30: =SUM(0.04166667)+B30 -> 0.38541668 | E30: =SUM('Raw data & Hourly Summary'!E116,'Raw data & Hourly Summary'!I116,'Raw data & Hourly Summary'!M116,'Raw data & Hourly Summary'!Q116,'Raw data & Hourly Summary'!U116) -> 667 | F30: =SUM('Raw data & Hourly Summary'!F116,'Raw data & Hourly Summary'!J116,'Raw data & Hourly Summary'!N116,'Raw data & Hourly Summary'!R116,'Raw data & Hourly Summary'!V116) -> 15 | G30: =SUM('Raw data & Hourly Summary'!G116,'Raw data & Hourly Summary'!K116,'Raw data & Hourly Summary'!O116,'Raw data & Hourly Summary'!S116,'Raw data & Hourly Summary'!W116) -> 21 | H30: =SUM(E30:G30) -> 703 | I30: =SUM('Raw data & Hourly Summary'!Y116,'Raw data & Hourly Summary'!AC116,'Raw data & Hourly Summary'!AG116,'Raw data & Hourly Summary'!AK116,'Raw data & Hourly Summary'!AO116) -> 505 | J30: =SUM('Raw data & Hourly Summary'!Z116,'Raw data & Hourly Summary'!AD116,'Raw data & Hourly Summary'!AH116,'Raw data & Hourly Summary'!AL116,'Raw data & Hourly Summary'!AP116) -> 8 | K30: =SUM('Raw data & Hourly Summary'!AA116,'Raw data & Hourly Summary'!AE116,'Raw data & Hourly Summary'!AI116,'Raw data & Hourly Summary'!AM116,'Raw data & Hourly Summary'!AQ116) -> 0 | L30: =SUM(I30:K30) -> 513 | M30: =SUM('Raw data & Hourly Summary'!E148,'Raw data & Hourly Summary'!I148,'Raw data & Hourly Summary'!M148,'Raw data & Hourly Summary'!Q148,'Raw data & Hourly Summary'!U148) -> 422 | N30: =SUM('Raw data & Hourly Summary'!F148,'Raw data & Hourly Summary'!J148,'Raw data & Hourly Summary'!N148,'Raw data & Hourly Summary'!R148,'Raw data & Hourly Summary'!V148) -> 10 | O30: =SUM('Raw data & Hourly Summary'!G148,'Raw data & Hourly Summary'!K148,'Raw data & Hourly Summary'!O148,'Raw data & Hourly Summary'!S148,'Raw data & Hourly Summary'!W148) -> 0 | P30: =SUM(M30:O30) -> 432 | Q30: =SUM('Raw data & Hourly Summary'!Y148,'Raw data & Hourly Summary'!AC148,'Raw data & Hourly Summary'!AG148,'Raw data & Hourly Summary'!AK148,'Raw data & Hourly Summary'!AO148) -> 451 | R30: =SUM('Raw data & Hourly Summary'!Z148,'Raw data & Hourly Summary'!AD148,'Raw data & Hourly Summary'!AH148,'Raw data & Hourly Summary'!AL148,'Raw data & Hourly Summary'!AP148) -> 12 | S30: =SUM('Raw data & Hourly Summary'!AA148,'Raw data & Hourly Summary'!AE148,'Raw data & Hourly Summary'!AI148,'Raw data & Hourly Summary'!AM148,'Raw data & Hourly Summary'!AQ148) -> 29 | T30: =SUM(Q30:S30) -> 492 | U30: =SUM('Raw data & Hourly Summary'!AS148,'Raw data & Hourly Summary'!AW148,'Raw data & Hourly Summary'!BA148,'Raw data & Hourly Summary'!BE148,'Raw data & Hourly Summary'!BI148) -> 123 | V30: =SUM('Raw data & Hourly Summary'!AT148,'Raw data & Hourly Summary'!AX148,'Raw data & Hourly Summary'!BB148,'Raw data & Hourly Summary'!BF148,'Raw data & Hourly Summary'!BJ148) -> 2 | W30: =SUM('Raw data & Hourly Summary'!AU148,'Raw data & Hourly Summary'!AY148,'Raw data & Hourly Summary'!BC148,'Raw data & Hourly Summary'!BG148,'Raw data & Hourly Summary'!BK148) -> 0 | X30: =SUM(U30:W30) -> 125 | Y30: =H30+L30+P30+T30+X30 -> 2265 | AG30: =IF($BD30=$Y30,B30,"") -> 0.34375001 | AH30: =IF($BD30=$Y30,E30,"") -> 667 | AI30: =IF($BD30=$Y30,F30,"") -> 15 | AJ30: =IF($BD30=$Y30,G30,"") -> 21 | AK30: =IF($BD30=$Y30,H30,"") -> 703 | AL30: =IF($BD30=$Y30,I30,"") -> 505 | AM30: =IF($BD30=$Y30,J30,"") -> 8 | AN30: =IF($BD30=$Y30,K30,"") -> 0 | AO30: =IF($BD30=$Y30,L30,"") -> 513 | ... BB30: =IF($BD30=$Y30,Y30,"") -> 2265 | BD30: =+BD31 -> 2265
